Workbook

Sheet Energi
B1: Energy 4 Outlet
A3: NO. | B3: KETERANGAN | C3: Total Harga | D3: day | E3: ket/day | F3: Total Harga
A4: 1 | B4: Sewa Lapak | C4: 1900000 | D4: 26 | E4: Day | F4: =C4/D4 -> 73076.923
A5: 2 | B5: Sewa Produksi | C5: 500000 | D5: 26 | E5: Day | F5: =C5/D5 -> 19230.769
A6: 3 | B6: Gas | C6: 1100000 | D6: 50 | E6: gas/bulan | F6: =C6/D6 -> 22000
A7: 4 | B7: Gaji 6 person | C7: 12900000 | D7: 26 | E7: Day | F7: =C7/D7 -> 496153.85
E9: all outlet/day | F9: =SUM(F4:F7) -> 610461.54
E10: 1 outlet/day | F10: =F9/4 -> 152615.38

Sheet Menu Summary
B1: ENERGI 611.000/300 PORSI | E1: KOTOR | F1: HPP | G1: ENERGI | H1: BERSIH | I1: BERSIH/BLN
E3: =SUM(L7:L72) -> 1722000 | F3: =SUM(M7:M72) -> 1051124 | G3: 610500 | H3: =E3-F3-G3 -> 60376 | I3: =H3*26 -> 1569776
A6: NO | B6: NAMA MENU | C6: RINCIAN MENU | D6: PCS | E6: HPP | F6: TOTAL HPP | G6: HPP PACK | H6: ENERGI/ TARGET 300pcs | I6: TOTAL COST | J6: HARGA JUAL | K6: TARGET/ DAY | L6: TOTAL KOTOR | M6: TOTAL COST/TARGET | N6: BERSIH/ TARGET | O6: TOTAL ENERGI | P6: PCS MENU
A7: 1 | B7: Dimsum Ori isi 4 | C7: Dimsum ori topping beef | D7: 4 | E7: 1761 | F7: =E7*D7 -> 7044 | G7: 834 | H7: 2100 | I7: =SUM(F7:H8) -> 10791 | J7: 16000 | K7: 10 | L7: =J7*K7 -> 160000 | M7: =I7*K7 -> 107910 | N7: =L7-M7 -> 52090 | O7: =H7*K7 -> 21000 | P7: =K7*D7 -> 40
C8: Chili Oil | D8: 1 | E8: 713 | F8: =E8*D8 -> 713 | G8: 100
A10: 2 | B10: Dimsum Ori isi 6 | C10: Dimsum ori topping beef | D10: 6 | E10: 1761 | F10: =E10*D10 -> 10566 | G10: 834 | H10: 2500 | I10: =SUM(F10:H11) -> 14713 | J10: 22000 | K10: 3 | L10: =J10*K10 -> 66000 | M10: =I10*K10 -> 44139 | N10: =L10-M10 -> 21861 | O10: =H10*K10 -> 7500 | P10: =K10*D10 -> 18
C11: Chili Oil | D11: 1 | E11: 713 | F11: =E11*D11 -> 713 | G11: 100
A13: 3 | B13: Dimsum Ori isi 8 | C13: Dimsum ori topping beef | D13: 8 | E13: 1761 | F13: =E13*D13 -> 14088 | G13: 834 | H13: 2500 | I13: =SUM(F13:H14) -> 18235 | J13: 28000 | K13: 2 | L13: =J13*K13 -> 56000 | M13: =I13*K13 -> 36470 | N13: =L13-M13 -> 19530 | O13: =H13*K13 -> 5000 | P13: =K13*D13 -> 16
C14: Chili Oil | D14: 1 | E14: 713 | F14: =E14*D14 -> 713 | G14: 100
A16: 4 | B16: Dimsum mentai isi 4 | C16: Dimsum ori topping beef | D16: 4 | E16: 1761 | F16: =E16*D16 -> 7044 | G16: 834 | H16: 2500 | I16: =SUM(F16:H18) -> 14387 | J16: 20000 | K16: 5 | L16: =J16*K16 -> 100000 | M16: =I16*K16 -> 71935 | N16: =L16-M16 -> 28065 | O16: =H16*K16 -> 12500 | P16: =K16*D16 -> 20
C17: Dimsum Mentai Sauce | D17: 4 | E17: 799 | F17: =E17*D17 -> 3196
C18: Chili Oil | D18: 1 | E18: 713 | F18: =E18*D18 -> 713 | G18: 100
A20: 5 | B20: Dimsum mentai isi 6 | C20: Dimsum ori topping beef | D20: 6 | E20: 1761 | F20: =E20*D20 -> 10566 | G20: 834 | H20: 2500 | I20: =SUM(F20:H22) -> 19507 | J20: 26000 | K20: 1 | L20: =J20*K20 -> 26000 | M20: =I20*K20 -> 19507 | N20: =L20-M20 -> 6493 | O20: =H20*K20 -> 2500 | P20: =K20*D20 -> 6
C21: Dimsum Mentai Sauce | D21: 6 | E21: 799 | F21: =E21*D21 -> 4794
C22: Chili Oil | D22: 1 | E22: 713 | F22: =E22*D22 -> 713 | G22: 100
A24: 8 | B24: Dimsum mentai isi 8 | C24: Dimsum ori topping beef | D24: 8 | E24: 1761 | F24: =E24*D24 -> 14088 | G24: 834 | H24: 2500 | I24: =SUM(F24:H26) -> 24627 | J24: 36000 | K24: 1 | L24: =J24*K24 -> 36000 | M24: =I24*K24 -> 24627 | N24: =L24-M24 -> 11373 | O24: =H24*K24 -> 2500 | P24: =K24*D24 -> 8
C25: Dimsum Mentai Sauce | D25: 8 | E25: 799 | F25: =E25*D25 -> 6392
C26: Chili Oil | D26: 1 | E26: 713 | F26: =E26*D26 -> 713 | G26: 100
A28: 9 | B28: Dimsum Chesee isi 4 | C28: Dimsum isi Keju | D28: 4 | E28: 2045 | F28: =E28*D28 -> 8180 | G28: 834 | H28: 2500 | I28: =SUM(F28:H29) -> 12327 | J28: 22000 | K28: 2 | L28: =J28*K28 -> 44000 | M28: =I28*K28 -> 24654 | N28: =L28-M28 -> 19346 | O28: =H28*K28 -> 5000 | P28: =K28*D28 -> 8
C29: Chili Oil | D29: 1 | E29: 713 | F29: =E29*D29 -> 713 | G29: 100
A31: 10 | B31: Dimsum Chesee isi 6 | C31: Dimsum isi Keju | D31: 6 | E31: 2045 | F31: =E31*D31 -> 12270 | G31: 834 | H31: 2500 | I31: =SUM(F31:H32) -> 16417 | J31: 31000 | K31: 1 | L31: =J31*K31 -> 31000 | M31: =I31*K31 -> 16417 | N31: =L31-M31 -> 14583 | O31: =H31*K31 -> 2500 | P31: =K31*D31 -> 6
C32: Chili Oil | D32: 1 | E32: 713 | F32: =E32*D32 -> 713 | G32: 100
A34: 11 | B34: Dimsum Chesee isi 8 | C34: Dimsum isi Keju | D34: 8 | E34: 2045 | F34: =E34*D34 -> 16360 | G34: 834 | H34: 2500 | I34: =SUM(F34:H35) -> 20507 | J34: 40000 | K34: 1 | L34: =J34*K34 -> 40000 | M34: =I34*K34 -> 20507 | N34: =L34-M34 -> 19493 | O34: =H34*K34 -> 2500 | P34: =K34*D34 -> 8
C35: Chili Oil | D35: 1 | E35: 713 | F35: =E35*D35 -> 713 | G35: 100
A37: 12 | B37: Dimsum MIX isi 6 | C37: Dimsum ori topping beef | D37: 4 | E37: 1761 | F37: =E37*D37 -> 7044 | G37: 834 | H37: 2500 | I37: =SUM(F37:H41) -> 19079 | J37: 29000 | K37: 1 | L37: =J37*K37 -> 29000 | M37: =I37*K37 -> 19079 | N37: =L37-M37 -> 9921 | O37: =H37*K37 -> 2500 | P37: {=K37*D37:D39} -> 4
C38: Dimsum isi Keju | D38: 2 | E38: 2045 | F38: =E38*D38 -> 4090 | P38: 2
C39: Dimsum Mentai Sauce | D39: 2 | E39: 799 | F39: =E39*D39 -> 1598 | P39: 2
C40: Bolognese Sauce | D40: 2 | E40: 1100 | F40: =E40*D40 -> 2200
C41: Chili Oil | D41: 1 | E41: 713 | F41: =E41*D41 -> 713 | G41: 100
A43: 13 | B43: Dimsum MIX isi 8 | C43: Dimsum ori topping beef | D43: 6 | E43: 1761 | F43: =E43*D43 -> 10566 | G43: 834 | H43: 2500 | I43: =SUM(F43:H47) -> 24500 | J43: 40000 | K43: 1 | L43: =J43*K43 -> 40000 | M43: =I43*K43 -> 24500 | N43: =L43-M43 -> 15500 | O43: =H43*K43 -> 2500 | P43: {=K43*D43:D45} -> 6
C44: Dimsum isi Keju | D44: 2 | E44: 2045 | F44: =E44*D44 -> 4090 | P44: 2
C45: Dimsum Mentai Sauce | D45: 3 | E45: 799 | F45: =E45*D45 -> 2397 | P45: 3
C46: Bolognese Sauce | D46: 3 | E46: 1100 | F46: =E46*D46 -> 3300
C47: Chili Oil | D47: 1 | E47: 713 | F47: =E47*D47 -> 713 | G47: 100
A49: 14 | B49: Lumpia Ori isi 3 | C49: Lumpia | D49: 3 | E49: 3339 | F49: =E49*D49 -> 10017 | G49: 834 | H49: 2500 | I49: =SUM(F49:H50) -> 14164 | J49: 22000 | K49: 4 | L49: =J49*K49 -> 88000 | M49: =I49*K49 -> 56656 | N49: =L49-M49 -> 31344 | O49: =H49*K49 -> 10000 | P49: =K49*D49 -> 12
C50: Chili Oil | D50: 1 | E50: 713 | F50: =E50*D50 -> 713 | G50: 100
A52: 15 | B52: Lumpia Ori isi 5 | C52: Lumpia | D52: 5 | E52: 3339 | F52: =E52*D52 -> 16695 | G52: 834 | H52: 2500 | I52: =SUM(F52:H53) -> 20842 | J52: 34000 | K52: 2 | L52: =J52*K52 -> 68000 | M52: =I52*K52 -> 41684 | N52: =L52-M52 -> 26316 | O52: =H52*K52 -> 5000 | P52: =K52*D52 -> 10
C53: Chili Oil | D53: 1 | E53: 713 | F53: =E53*D53 -> 713 | G53: 100
A55: 16 | B55: Lumpia Mentai isi 3 | C55: Lumpia | D55: 3 | E55: 3339 | F55: =E55*D55 -> 10017 | G55: 834 | H55: 2500 | I55: =SUM(F55:H57) -> 16561 | J55: 26000 | K55: 2 | L55: =J55*K55 -> 52000 | M55: =I55*K55 -> 33122 | N55: =L55-M55 -> 18878 | O55: =H55*K55 -> 5000 | P55: =K55*D55 -> 6
C56: Chili Oil | D56: 1 | E56: 713 | F56: =E56*D56 -> 713 | G56: 100
...

Sheet Master Bahan
A3: NO | B3: NAMA BAHAN | C3: Weight | D3: UOM | E3: HARGA | F3: TOTAL
A4: 1 | B4: Ayam Fillet Paha | C4: 1000 | D4: kg | E4: 57 | F4: =E4*C4 -> 57000
A5: 2 | B5: Telur Ayam | C5: 1000 | D5: gr | E5: 27 | F5: =E5*C5 -> 27000
A6: 3 | B6: Daging Giling sapi | C6: 1000 | D6: gr | E6: 100 | F6: =E6*C6 -> 100000
A7: 4 | B7: Daun Bawang | C7: 1000 | D7: gr | E7: 20 | F7: =E7*C7 -> 20000
A8: 5 | B8: Bawang Bombay | C8: 1000 | D8: gr | E8: 50 | F8: =E8*C8 -> 50000
A9: 6 | B9: Bawang Putih | C9: 1000 | D9: gr | E9: 40 | F9: =E9*C9 -> 40000
A10: 7 | B10: Minyak Wijen | C10: 600 | D10: gr | E10: 75 | F10: =E10*C10 -> 45000
A11: 8 | B11: Kecap Asin | C11: 600 | D11: ml | E11: 60 | F11: =E11*C11 -> 36000
A12: 9 | B12: Saori saus Tiram | C12: 1000 | D12: gr | E12: 53 | F12: =E12*C12 -> 53000
A13: 10 | B13: Chicken Powder Knorr | C13: 1000 | D13: gr | E13: 105 | F13: =E13*C13 -> 105000
A14: 11 | B14: Sasa | C14: 1000 | D14: gr | E14: 50 | F14: =E14*C14 -> 50000
A15: 12 | B15: Garam | C15: 1000 | D15: gr | E15: 14 | F15: =E15*C15 -> 14000
... A44: 41 | B44: beef patty | C44: 280 | D44: gr | E44: 42.857143 | F44: =E44*C44 -> 12000
A45: 42

Sheet All Sauce
I1: 0.1
A2: 1 | B2: NAMA | C2: INGREDIENTS | D2: QTY | E2: UOM | F2: HARSAT | G2: PRICE | H2: COST | I2: Energi | J2: TOTAL COST
B3: Saus Dimsum | C3: Saus dimsum | D3: 25 | E3: gr | F3: =VLOOKUP(C3,'Master Bahan'!$B$4:$G$44,4,0) -> 18 | G3: =F3*D3 -> 450 | H3: =SUM(G3:G4) -> 459.47368 | I3: =H3*$I$1 -> 45.947368 | J3: =H3+I3 -> 505.42105
C4: Air Mineral | D4: 30 | F4: =VLOOKUP(C4,'Master Bahan'!$B$4:$G$44,4,0) -> 0.31578947 | G4: =F4*D4 -> 9.4736841
A6: 2 | B6: NAMA | C6: INGREDIENTS | D6: QTY | E6: UOM | F6: HARSAT | G6: PRICE | H6: COST | I6: Energi | J6: TOTAL COST
B7: Chili Oil | C7: Minyak Goreng | D7: 17.241 | E7: ml | F7: =VLOOKUP(C7,'Master Bahan'!$B$4:$G$44,4,0) -> 19 | G7: =F7*D7 -> 327.579 | H7: =SUM(G7:G17) -> 647.95456 | I7: =H7*$I$1 -> 64.795456 | J7: =H7+I7 -> 712.75001
C8: Cabe Kering | D8: 1.724 | E8: gr | F8: =VLOOKUP(C8,'Master Bahan'!$B$4:$G$44,4,0) -> 95 | G8: =F8*D8 -> 163.78
C9: Lada | D9: 0.034 | E9: gr | F9: =VLOOKUP(C9,'Master Bahan'!$B$4:$G$44,4,0) -> 305.55556 | G9: =F9*D9 -> 10.388889
C10: Kapulaga | D10: 0.01 | E10: gr | F10: =VLOOKUP(C10,'Master Bahan'!$B$4:$G$44,4,0) -> 13.333333 | G10: =F10*D10 -> 0.13333333
C11: Kayu Manis | D11: 0.04 | E11: gr | F11: =VLOOKUP(C11,'Master Bahan'!$B$4:$G$44,4,0) -> 6.6666667 | G11: =F11*D11 -> 0.26666667
C12: Garam | D12: 0.26 | E12: gr | F12: =VLOOKUP(C12,'Master Bahan'!$B$4:$G$44,4,0) -> 14 | G12: =F12*D12 -> 3.64
C13: Gula pasir | D13: 0.65 | E13: gr | F13: =VLOOKUP(C13,'Master Bahan'!$B$4:$G$44,4,0) -> 18 | G13: =F13*D13 -> 11.7
C14: Cengkeh | D14: 0.02 | E14: gr | F14: =VLOOKUP(C14,'Master Bahan'!$B$4:$G$44,4,0) -> 13.333333 | G14: =F14*D14 -> 0.26666667
C15: Sasa | D15: 0.26 | E15: gr | F15: =VLOOKUP(C15,'Master Bahan'!$B$4:$G$44,4,0) -> 50 | G15: =F15*D15 -> 13
C16: Daun Bawang | D16: 0.86 | E16: gr | F16: =VLOOKUP(C16,'Master Bahan'!$B$4:$G$44,4,0) -> 20 | G16: =F16*D16 -> 17.2
C17: Cup chili oil | D17: 1 | E17: pcs | F17: 100 | G17: =F17*D17 -> 100
A19: 3 | B19: NAMA | C19: INGREDIENTS | D19: QTY | E19: UOM | F19: HARSAT | G19: PRICE | H19: COST | I19: Energi | J19: TOTAL COST
B20: Garlic Sauce | C20: Bawang Putih | D20: 8 | E20: gr | F20: =VLOOKUP(C20,'Master Bahan'!$B$4:$G$44,4,0) -> 40 | G20: =F20*D20 -> 320 | H20: =SUM(G20:G24) -> 1952.7611 | I20: =H20*$I$1 -> 195.27611 | J20: =H20+I20 -> 2148.0372
B21: 38pcs/1 recipe | C21: Mamayo | D21: 52.64 | E21: gr | F21: =VLOOKUP(C21,'Master Bahan'!$B$4:$G$44,4,0) -> 25 | G21: =F21*D21 -> 1316
B22: 60g/pcs | C22: Chicken Powder Knorr | D22: 0.53 | E22: gr | F22: =VLOOKUP(C22,'Master Bahan'!$B$4:$G$44,4,0) -> 105 | G22: =F22*D22 -> 55.65
C23: Lada | D23: 0.2 | E23: gr | F23: =VLOOKUP(C23,'Master Bahan'!$B$4:$G$44,4,0) -> 305.55556 | G23: =F23*D23 -> 61.111111
C24: Parsley | D24: 0.2 | E24: gr | F24: =VLOOKUP(C24,'Master Bahan'!$B$4:$G$44,4,0) -> 1000 | G24: =F24*D24 -> 200
A26: 4 | B26: NAMA | C26: INGREDIENTS | D26: QTY | E26: UOM | F26: HARSAT | G26: PRICE | H26: COST | I26: Energi | J26: TOTAL COST
B27: Lava Sauce | C27: Saus Lava | D27: 50 | E27: gr | F27: =VLOOKUP(C27,'Master Bahan'!$B$4:$G$44,4,0) -> 17 | G27: =F27*D27 -> 850 | H27: =SUM(G27:G28) -> 1450 | I27: =H27*$I$1 -> 145 | J27: =H27+I27 -> 1595
B28: 20pcs/1 recipe | C28: Gourmet BBQ | D28: 12.5 | E28: gr | F28: =VLOOKUP(C28,'Master Bahan'!$B$4:$G$44,4,0) -> 48 | G28: =F28*D28 -> 600
B29: 60g/pcs
A31: 5 | B31: NAMA | C31: INGREDIENTS | D31: QTY | E31: UOM | F31: HARSAT | G31: PRICE | H31: COST | I31: Energi | J31: TOTAL COST
B32: Chesee Sauce | C32: Keju quickmelt | D32: 15.4 | E32: gr | F32: =VLOOKUP(C32,'Master Bahan'!$B$4:$G$44,4,0) -> 100 | G32: =F32*D32 -> 1540 | H32: =SUM(G32:G36) -> 2106.8879 | I32: =H32*$I$1 -> 210.68879 | J32: =H32+I32 -> 2317.5767
B33: 39pcs/1 recipe | C33: Air Mineral | D33: 38.5 | E33: ml | F33: =VLOOKUP(C33,'Master Bahan'!$B$4:$G$44,4,0) -> 0.31578947 | G33: =F33*D33 -> 12.157895
B34: 60g/pcs | C34: Maizena | D34: 3.1 | E34: gr | F34: =VLOOKUP(C34,'Master Bahan'!$B$4:$G$44,4,0) -> 50 | G34: =F34*D34 -> 155
C35: Bubuk Keju | D35: 3.34 | E35: gr | F35: =VLOOKUP(C35,'Master Bahan'!$B$4:$G$44,4,0) -> 112 | G35: =F35*D35 -> 374.08
C36: Creamer | D36: 0.513 | E36: gr | F36: =VLOOKUP(C36,'Master Bahan'!$B$4:$G$44,4,0) -> 50 | G36: =F36*D36 -> 25.65
A38: 6 | B38: NAMA | C38: INGREDIENTS | D38: QTY | E38: UOM | F38: HARSAT | G38: PRICE | H38: COST | I38: Energi | J38: TOTAL COST
B39: Saus Bolognese | C39: Daging Giling sapi | D39: 3.17 | E39: gr | F39: =VLOOKUP(C39,'Master Bahan'!$B$4:$G$44,4,0) -> 100 | G39: =F39*D39 -> 317 | H39: =SUM(G39:G46) -> 994.316 | I39: =H39*$I$1 -> 99.4316 | J39: =H39+I39 -> 1093.7476
B40: 79pcs/recipe | C40: Bawang Bombay | D40: 1 | E40: gr | F40: =VLOOKUP(C40,'Master Bahan'!$B$4:$G$44,4,0) -> 50 | G40: =F40*D40 -> 50
B41: 35g/pcs | C41: Saus tomat | D41: 25.32 | E41: kg | F41: =VLOOKUP(C41,'Master Bahan'!$B$4:$G$44,4,0) -> 15 | G41: =F41*D41 -> 379.8
C42: Bawang Putih | D42: 4.33 | E42: gr | F42: =VLOOKUP(C42,'Master Bahan'!$B$4:$G$44,4,0) -> 40 | G42: =F42*D42 -> 173.2
C43: Oregano | D43: 0.05064 | E43: gr | F43: =VLOOKUP(C43,'Master Bahan'!$B$4:$G$44,4,0) -> 733.33333 | G43: =F43*D43 -> 37.136
C44: Gula pasir | D44: 1.14 | E44: gr | F44: =VLOOKUP(C44,'Master Bahan'!$B$4:$G$44,4,0) -> 18 | G44: =F44*D44 -> 20.52
C45: Garam | D45: 0.14 | E45: gr | F45: =VLOOKUP(C45,'Master Bahan'!$B$4:$G$44,4,0) -> 14 | G45: =F45*D45 -> 1.96
...

Sheet Packaging
A1: NO | B1: UTENSIL | C1: QTY | D1: UOM | E1: HARSAT | F1: PRICE
A2: 1 | B2: box pack dimsum | C2: 425 | D2: Pcs | E2: =200000/C2 -> 470.58824 | F2: =E2*C2 -> 200000
A3: 2 | B3: Sumpit | C3: 3000 | D3: Pcs | E3: 88 | F3: =E3*C3 -> 264000
A4: 3 | B4: Cup | C4: 350 | D4: Pcs | E4: 100 | F4: =E4*C4 -> 35000
A5: 4 | B5: Plastik dimsum 24 | C5: 40 | D5: Pcs | E5: 275 | F5: =E5*C5 -> 11000
A6: 5 | B6: Pack chikuro | C6: 350 | D6: Pcs | E6: 75 | F6: =E6*C6 -> 26250
A7: 6 | B7: Plastik Chikuro | C7: 350 | D7: Pcs | E7: 150 | F7: =E7*C7 -> 52500

Sheet Mentai Sauce
I1: 0.1
A2: NO | B2: NAMA | C2: INGREDIENTS | D2: QTY | E2: UOM | F2: HARSAT | G2: PRICE | H2: COST | I2: Energi | J2: TOTAL COST
B3: Dimsum Mentai Sauce | C3: Mamayo | D3: 22 | E3: gr | F3: =VLOOKUP(C3,'Master Bahan'!$B$4:$G$44,4,0) -> 25 | G3: =F3*D3 -> 550 | H3: =SUM(G3:G8) -> 726.53577 | I3: =H3*$I$1 -> 72.653577 | J3: =H3+I3 -> 799.18935
B4: 130pcs/1 recipe | C4: Saus Sambal | D4: 4.62 | E4: gr | F4: =VLOOKUP(C4,'Master Bahan'!$B$4:$G$44,4,0) -> 17 | G4: =F4*D4 -> 78.54
B5: 30g/pcs | C5: Saus Tomat | D5: 3.2 | E5: gr | F5: =VLOOKUP(C5,'Master Bahan'!$B$4:$G$44,4,0) -> 15 | G5: =F5*D5 -> 48
C6: Kikoman Manis | D6: 0.31 | E6: gr | F6: =VLOOKUP(C6,'Master Bahan'!$B$4:$G$44,4,0) -> 56.5 | G6: =F6*D6 -> 17.515
C7: Minyak Wijen | D7: 0.31 | E7: gr | F7: =VLOOKUP(C7,'Master Bahan'!$B$4:$G$44,4,0) -> 75 | G7: =F7*D7 -> 23.25
C8: Kecap Asin | D8: 0.15384615 | E8: gr | F8: =VLOOKUP(C8,'Master Bahan'!$B$4:$G$44,4,0) -> 60 | G8: =F8*D8 -> 9.2307692
A10: NO | B10: NAMA | C10: INGREDIENTS | D10: QTY | E10: UOM | F10: HARSAT | G10: PRICE | H10: COST | I10: Energi | J10: TOTAL COST
B11: Lumpia Mentai Sauce | C11: Mamayo | D11: 22 | E11: gr | F11: =VLOOKUP(C11,'Master Bahan'!$B$4:$G$44,4,0) -> 25 | G11: =F11*D11 -> 550 | H11: =SUM(G11:G16) -> 726.53577 | I11: =H11*$I$1 -> 72.653577 | J11: =H11+I11 -> 799.18935
B12: 130pcs/1 recipe | C12: Saus Sambal | D12: 4.62 | E12: gr | F12: =VLOOKUP(C12,'Master Bahan'!$B$4:$G$44,4,0) -> 17 | G12: =F12*D12 -> 78.54
B13: 30g/pcs | C13: Saus Tomat | D13: 3.2 | E13: gr | F13: =VLOOKUP(C13,'Master Bahan'!$B$4:$G$44,4,0) -> 15 | G13: =F13*D13 -> 48
C14: Kikoman Manis | D14: 0.31 | E14: gr | F14: =VLOOKUP(C14,'Master Bahan'!$B$4:$G$44,4,0) -> 56.5 | G14: =F14*D14 -> 17.515
C15: Minyak Wijen | D15: 0.31 | E15: gr | F15: =VLOOKUP(C15,'Master Bahan'!$B$4:$G$44,4,0) -> 75 | G15: =F15*D15 -> 23.25
C16: Kecap Asin | D16: 0.15384615 | E16: gr | F16: =VLOOKUP(C16,'Master Bahan'!$B$4:$G$44,4,0) -> 60 | G16: =F16*D16 -> 9.2307692
A18: NO | B18: NAMA | C18: INGREDIENTS | D18: QTY | E18: UOM | F18: HARSAT | G18: PRICE | H18: COST | I18: Energi | J18: TOTAL COST
B19: Chikuro Mentai Sauce | C19: Mamayo | D19: 43 | E19: gr | F19: =VLOOKUP(C19,'Master Bahan'!$B$4:$G$44,4,0) -> 25 | G19: =F19*D19 -> 1075 | H19: =SUM(G19:G24) -> 1442.15 | I19: =H19*$I$1 -> 144.215 | J19: =H19+I19 -> 1586.365
B20: 65cs/1 recipe | C20: Saus Sambal | D20: 9.3 | E20: gr | F20: =VLOOKUP(C20,'Master Bahan'!$B$4:$G$44,4,0) -> 17 | G20: =F20*D20 -> 158.1
B21: 60g/pcs | C21: Saus Tomat | D21: 6.2 | E21: gr | F21: =VLOOKUP(C21,'Master Bahan'!$B$4:$G$44,4,0) -> 15 | G21: =F21*D21 -> 93
C22: Kikoman Manis | D22: 0.7 | E22: gr | F22: =VLOOKUP(C22,'Master Bahan'!$B$4:$G$44,4,0) -> 56.5 | G22: =F22*D22 -> 39.55
C23: Minyak Wijen | D23: 0.7 | E23: gr | F23: =VLOOKUP(C23,'Master Bahan'!$B$4:$G$44,4,0) -> 75 | G23: =F23*D23 -> 52.5
C24: Kecap Asin | D24: 0.4 | E24: gr | F24: =VLOOKUP(C24,'Master Bahan'!$B$4:$G$44,4,0) -> 60 | G24: =F24*D24 -> 24

Sheet Chikuro
I1: 0.1
A2: NO | B2: NAMA | C2: INGREDIENTS | D2: QTY | E2: UOM | F2: HARSAT | G2: PRICE | H2: COST | I2: Energi | J2: TOTAL COST
B3: Chikuro Basic | C3: Ayam Fillet Paha | D3: 100 | E3: gr | F3: =VLOOKUP(C3,'Master Bahan'!$B$4:$G$44,4,0) -> 57 | G3: =F3*D3 -> 5700 | H3: =SUM(G3:G15) -> 8624.1111 | I3: =H3*$I$1 -> 862.41111 | J3: =H3+I3 -> 9486.5222
C4: Telur Ayam | D4: 5.5 | E4: gr | F4: =VLOOKUP(C4,'Master Bahan'!$B$4:$G$44,4,0) -> 27 | G4: =F4*D4 -> 148.5
C5: Lada | D5: 0.2 | E5: gr | F5: =VLOOKUP(C5,'Master Bahan'!$B$4:$G$44,4,0) -> 305.55556 | G5: =F5*D5 -> 61.111111
C6: Bawang Putih | D6: 2 | E6: gr | F6: =VLOOKUP(C6,'Master Bahan'!$B$4:$G$44,4,0) -> 40 | G6: =F6*D6 -> 80
C7: Saori saus Tiram | D7: 1.5 | E7: gr | F7: =VLOOKUP(C7,'Master Bahan'!$B$4:$G$44,4,0) -> 53 | G7: =F7*D7 -> 79.5
C8: Chicken Powder Knorr | D8: 2 | E8: gr | F8: =VLOOKUP(C8,'Master Bahan'!$B$4:$G$44,4,0) -> 105 | G8: =F8*D8 -> 210
C9: Sasa | D9: 1 | E9: gr | F9: =VLOOKUP(C9,'Master Bahan'!$B$4:$G$44,4,0) -> 50 | G9: =F9*D9 -> 50
C10: Garam | D10: 0.5 | E10: gr | F10: =VLOOKUP(C10,'Master Bahan'!$B$4:$G$44,4,0) -> 14 | G10: =F10*D10 -> 7
C11: Minyak Goreng | D11: 50 | E11: ml | F11: =VLOOKUP(C11,'Master Bahan'!$B$4:$G$44,4,0) -> 19 | G11: =F11*D11 -> 950
C12: Tepung Tapioka | D12: 10 | E12: gr | F12: =VLOOKUP(C12,'Master Bahan'!$B$4:$G$44,4,0) -> 22 | G12: =F12*D12 -> 220
C13: Rumput Laut | D13: 2 | E13: gr | F13: =VLOOKUP(C13,'Master Bahan'!$B$4:$G$44,4,0) -> 416 | G13: =F13*D13 -> 832
C14: Tepung Panir | D14: 13 | E14: gr | F14: =VLOOKUP(C14,'Master Bahan'!$B$4:$G$44,4,0) -> 22 | G14: =F14*D14 -> 286
A17: NO | B17: NAMA | C17: INGREDIENTS | D17: QTY | E17: UOM | F17: HARSAT | G17: PRICE | H17: COST | I17: Energi | J17: TOTAL COST
B18: Chikuro Garlic Sauce | C18: Ayam Fillet Paha | D18: 100 | E18: gr | F18: =VLOOKUP(C18,'Master Bahan'!$B$4:$G$44,4,0) -> 57 | G18: =F18*D18 -> 5700 | H18: =SUM(G18:G30) -> 8624.1111 | I18: =H18*$I$1 -> 862.41111 | J18: =H18+I18 -> 9486.5222
C19: Telur Ayam | D19: 5.5 | E19: gr | F19: =VLOOKUP(C19,'Master Bahan'!$B$4:$G$44,4,0) -> 27 | G19: =F19*D19 -> 148.5
C20: Lada | D20: 0.2 | E20: gr | F20: =VLOOKUP(C20,'Master Bahan'!$B$4:$G$44,4,0) -> 305.55556 | G20: =F20*D20 -> 61.111111
C21: Bawang Putih | D21: 2 | E21: gr | F21: =VLOOKUP(C21,'Master Bahan'!$B$4:$G$44,4,0) -> 40 | G21: =F21*D21 -> 80
C22: Saori saus Tiram | D22: 1.5 | E22: gr | F22: =VLOOKUP(C22,'Master Bahan'!$B$4:$G$44,4,0) -> 53 | G22: =F22*D22 -> 79.5
C23: Chicken Powder Knorr | D23: 2 | E23: gr | F23: =VLOOKUP(C23,'Master Bahan'!$B$4:$G$44,4,0) -> 105 | G23: =F23*D23 -> 210
C24: Sasa | D24: 1 | E24: gr | F24: =VLOOKUP(C24,'Master Bahan'!$B$4:$G$44,4,0) -> 50 | G24: =F24*D24 -> 50
C25: Garam | D25: 0.5 | E25: gr | F25: =VLOOKUP(C25,'Master Bahan'!$B$4:$G$44,4,0) -> 14 | G25: =F25*D25 -> 7
C26: Minyak Goreng | D26: 50 | E26: ml | F26: =VLOOKUP(C26,'Master Bahan'!$B$4:$G$44,4,0) -> 19 | G26: =F26*D26 -> 950
C27: Tepung Tapioka | D27: 10 | E27: gr | F27: =VLOOKUP(C27,'Master Bahan'!$B$4:$G$44,4,0) -> 22 | G27: =F27*D27 -> 220
C28: Rumput Laut | D28: 2 | E28: gr | F28: =VLOOKUP(C28,'Master Bahan'!$B$4:$G$44,4,0) -> 416 | G28: =F28*D28 -> 832
C29: Tepung Panir | D29: 13 | E29: gr | F29: =VLOOKUP(C29,'Master Bahan'!$B$4:$G$44,4,0) -> 22 | G29: =F29*D29 -> 286
C30: Garlic Sauce | E30: gr | G30: =F30*D30 -> 0
A32: NO | B32: NAMA | C32: INGREDIENTS | D32: QTY | E32: UOM | F32: HARSAT | G32: PRICE | H32: COST | I32: Energi | J32: TOTAL COST
B33: Chikuro Lava Sauce | C33: Ayam Fillet Paha | D33: 100 | E33: gr | F33: =VLOOKUP(C33,'Master Bahan'!$B$4:$G$44,4,0) -> 57 | G33: =F33*D33 -> 5700 | H33: =SUM(G33:G45) -> 8624.1111 | I33: =H33*$I$1 -> 862.41111 | J33: =H33+I33 -> 9486.5222
C34: Telur Ayam | D34: 5.5 | E34: gr | F34: =VLOOKUP(C34,'Master Bahan'!$B$4:$G$44,4,0) -> 27 | G34: =F34*D34 -> 148.5
C35: Lada | D35: 0.2 | E35: gr | F35: =VLOOKUP(C35,'Master Bahan'!$B$4:$G$44,4,0) -> 305.55556 | G35: =F35*D35 -> 61.111111
C36: Bawang Putih | D36: 2 | E36: gr | F36: =VLOOKUP(C36,'Master Bahan'!$B$4:$G$44,4,0) -> 40 | G36: =F36*D36 -> 80
C37: Saori saus Tiram | D37: 1.5 | E37: gr | F37: =VLOOKUP(C37,'Master Bahan'!$B$4:$G$44,4,0) -> 53 | G37: =F37*D37 -> 79.5
C38: Chicken Powder Knorr | D38: 2 | E38: gr | F38: =VLOOKUP(C38,'Master Bahan'!$B$4:$G$44,4,0) -> 105 | G38: =F38*D38 -> 210
C39: Sasa | D39: 1 | E39: gr | F39: =VLOOKUP(C39,'Master Bahan'!$B$4:$G$44,4,0) -> 50 | G39: =F39*D39 -> 50
C40: Garam | D40: 0.5 | E40: gr | F40: =VLOOKUP(C40,'Master Bahan'!$B$4:$G$44,4,0) -> 14 | G40: =F40*D40 -> 7
C41: Minyak Goreng | D41: 50 | E41: ml | F41: =VLOOKUP(C41,'Master Bahan'!$B$4:$G$44,4,0) -> 19 | G41: =F41*D41 -> 950
C42: Tepung Tapioka | D42: 10 | E42: gr | F42: =VLOOKUP(C42,'Master Bahan'!$B$4:$G$44,4,0) -> 22 | G42: =F42*D42 -> 220
C43: Rumput Laut | D43: 2 | E43: gr | F43: =VLOOKUP(C43,'Master Bahan'!$B$4:$G$44,4,0) -> 416 | G43: =F43*D43 -> 832
...

Sheet Lumpia
I1: 0.1
A2: NO | B2: NAMA | C2: INGREDIENTS | D2: QTY | E2: UOM | F2: HARSAT | G2: PRICE | H2: COST | I2: Energi | J2: TOTAL COST
B3: Lumpia keju ori | C3: Ayam Fillet Paha | D3: 25 | E3: gr | F3: =VLOOKUP(C3,'Master Bahan'!$B$4:$G$44,4,0) -> 57 | G3: =F3*D3 -> 1425 | H3: =SUM(G3:G16) -> 3035.825 | I3: =H3*$I$1 -> 303.5825 | J3: =H3+I3 -> 3339.4075
C4: Telur Ayam | D4: 1.375 | E4: gr | F4: =VLOOKUP(C4,'Master Bahan'!$B$4:$G$44,4,0) -> 27 | G4: =F4*D4 -> 37.125
C5: Kulit Lumpia | D5: 2 | E5: pcs | F5: =VLOOKUP(C5,'Master Bahan'!$B$4:$G$44,4,0) -> 240 | G5: =F5*D5 -> 480
C6: Bawang Putih | D6: 0.625 | E6: gr | F6: =VLOOKUP(C6,'Master Bahan'!$B$4:$G$44,4,0) -> 40 | G6: =F6*D6 -> 25
C7: Minyak Wijen | D7: 0.5 | E7: gr | F7: =VLOOKUP(C7,'Master Bahan'!$B$4:$G$44,4,0) -> 75 | G7: =F7*D7 -> 37.5
C8: Kecap Asin | D8: 0.125 | E8: gr | F8: =VLOOKUP(C8,'Master Bahan'!$B$4:$G$44,4,0) -> 60 | G8: =F8*D8 -> 7.5
C9: Saori saus Tiram | D9: 0.75 | E9: gr | F9: =VLOOKUP(C9,'Master Bahan'!$B$4:$G$44,4,0) -> 53 | G9: =F9*D9 -> 39.75
C10: Chicken Powder Knorr | D10: 0.5 | E10: gr | F10: =VLOOKUP(C10,'Master Bahan'!$B$4:$G$44,4,0) -> 105 | G10: =F10*D10 -> 52.5
C11: Sasa | D11: 0.375 | E11: gr | F11: =VLOOKUP(C11,'Master Bahan'!$B$4:$G$44,4,0) -> 50 | G11: =F11*D11 -> 18.75
C12: Garam | D12: 0.175 | E12: gr | F12: =VLOOKUP(C12,'Master Bahan'!$B$4:$G$44,4,0) -> 14 | G12: =F12*D12 -> 2.45
C13: Gula pasir | D13: 0.625 | E13: gr | F13: =VLOOKUP(C13,'Master Bahan'!$B$4:$G$44,4,0) -> 18 | G13: =F13*D13 -> 11.25
C14: Keju quickmelt | D14: 8 | E14: gr | F14: =VLOOKUP(C14,'Master Bahan'!$B$4:$G$44,4,0) -> 100 | G14: =F14*D14 -> 800
C15: Tepung Tapioka | D15: 4.5 | E15: gr | F15: =VLOOKUP(C15,'Master Bahan'!$B$4:$G$44,4,0) -> 22 | G15: =F15*D15 -> 99
A17: NO | B17: NAMA | C17: INGREDIENTS | D17: QTY | E17: UOM | F17: HARSAT | G17: PRICE | H17: COST | I17: Energi | J17: TOTAL COST
B18: Lumpia keju mentai | C18: Ayam Fillet Paha | D18: 25 | E18: gr | F18: =VLOOKUP(C18,'Master Bahan'!$B$4:$G$44,4,0) -> 57 | G18: =F18*D18 -> 1425 | H18: =SUM(G18:G31) -> 3035.825 | I18: =H18*$I$1 -> 303.5825 | J18: =H18+I18 -> 3339.4075
C19: Telur Ayam | D19: 1.375 | E19: gr | F19: =VLOOKUP(C19,'Master Bahan'!$B$4:$G$44,4,0) -> 27 | G19: =F19*D19 -> 37.125
C20: Kulit Lumpia | D20: 2 | E20: pcs | F20: =VLOOKUP(C20,'Master Bahan'!$B$4:$G$44,4,0) -> 240 | G20: =F20*D20 -> 480
C21: Bawang Putih | D21: 0.625 | E21: gr | F21: =VLOOKUP(C21,'Master Bahan'!$B$4:$G$44,4,0) -> 40 | G21: =F21*D21 -> 25
C22: Minyak Wijen | D22: 0.5 | E22: gr | F22: =VLOOKUP(C22,'Master Bahan'!$B$4:$G$44,4,0) -> 75 | G22: =F22*D22 -> 37.5
C23: Kecap Asin | D23: 0.125 | E23: gr | F23: =VLOOKUP(C23,'Master Bahan'!$B$4:$G$44,4,0) -> 60 | G23: =F23*D23 -> 7.5
C24: Saori saus Tiram | D24: 0.75 | E24: gr | F24: =VLOOKUP(C24,'Master Bahan'!$B$4:$G$44,4,0) -> 53 | G24: =F24*D24 -> 39.75
C25: Chicken Powder Knorr | D25: 0.5 | E25: gr | F25: =VLOOKUP(C25,'Master Bahan'!$B$4:$G$44,4,0) -> 105 | G25: =F25*D25 -> 52.5
C26: Sasa | D26: 0.375 | E26: gr | F26: =VLOOKUP(C26,'Master Bahan'!$B$4:$G$44,4,0) -> 50 | G26: =F26*D26 -> 18.75
C27: Garam | D27: 0.175 | E27: gr | F27: =VLOOKUP(C27,'Master Bahan'!$B$4:$G$44,4,0) -> 14 | G27: =F27*D27 -> 2.45
C28: Gula pasir | D28: 0.625 | E28: gr | F28: =VLOOKUP(C28,'Master Bahan'!$B$4:$G$44,4,0) -> 18 | G28: =F28*D28 -> 11.25
C29: Keju quickmelt | D29: 8 | E29: gr | F29: =VLOOKUP(C29,'Master Bahan'!$B$4:$G$44,4,0) -> 100 | G29: =F29*D29 -> 800
C30: Tepung Tapioka | D30: 4.5 | E30: gr | F30: =VLOOKUP(C30,'Master Bahan'!$B$4:$G$44,4,0) -> 22 | G30: =F30*D30 -> 99
C31: Mentai Sauce | E31: gr

Sheet Dimsum
I1: 0.1
A2: NO | B2: NAMA | C2: INGREDIENTS | D2: QTY | E2: UOM | F2: HARSAT | G2: PRICE | H2: COST | I2: Energi | J2: TOTAL COST
B3: Dimsum ori topping wortel | C3: Ayam Fillet Paha | D3: 20 | E3: gr | F3: =VLOOKUP(C3,'Master Bahan'!$B$4:$G$44,4,0) -> 57 | G3: =F3*D3 -> 1140 | H3: =SUM(G3:G16) -> 1572.6387 | I3: =H3*$I$1 -> 157.26387 | J3: =H3+I3 -> 1729.9026
C4: Telur Ayam | D4: 1.1 | E4: gr | F4: =VLOOKUP(C4,'Master Bahan'!$B$4:$G$44,4,0) -> 27 | G4: =F4*D4 -> 29.7
C5: Daun Bawang | D5: 1 | E5: gr | F5: =VLOOKUP(C5,'Master Bahan'!$B$4:$G$44,4,0) -> 20 | G5: =F5*D5 -> 20
C6: Bawang Putih | D6: 0.5 | E6: gr | F6: =VLOOKUP(C6,'Master Bahan'!$B$4:$G$44,4,0) -> 40 | G6: =F6*D6 -> 20
C7: Minyak Wijen | D7: 0.4 | E7: gr | F7: =VLOOKUP(C7,'Master Bahan'!$B$4:$G$44,4,0) -> 75 | G7: =F7*D7 -> 30
C8: Kecap Asin | D8: 0.1 | E8: gr | F8: =VLOOKUP(C8,'Master Bahan'!$B$4:$G$44,4,0) -> 60 | G8: =F8*D8 -> 6
C9: Saori saus Tiram | D9: 0.6 | E9: gr | F9: =VLOOKUP(C9,'Master Bahan'!$B$4:$G$44,4,0) -> 53 | G9: =F9*D9 -> 31.8
C10: Chicken Powder Knorr | D10: 0.4 | E10: gr | F10: =VLOOKUP(C10,'Master Bahan'!$B$4:$G$44,4,0) -> 105 | G10: =F10*D10 -> 42
C11: Sasa | D11: 0.3 | E11: gr | F11: =VLOOKUP(C11,'Master Bahan'!$B$4:$G$44,4,0) -> 50 | G11: =F11*D11 -> 15
C12: Garam | D12: 0.14 | E12: gr | F12: =VLOOKUP(C12,'Master Bahan'!$B$4:$G$44,4,0) -> 14 | G12: =F12*D12 -> 1.96
C13: Gula Pasir | D13: 0.5 | E13: gr | F13: =VLOOKUP(C13,'Master Bahan'!$B$4:$G$44,4,0) -> 18 | G13: =F13*D13 -> 9
C14: Kulit Dimsum | D14: 1 | E14: pcs | F14: =VLOOKUP(C14,'Master Bahan'!$B$4:$G$44,4,0) -> 132.97872 | G14: =F14*D14 -> 132.97872
C15: Tepung Tapioka | D15: 3.6 | E15: gr | F15: =VLOOKUP(C15,'Master Bahan'!$B$4:$G$44,4,0) -> 22 | G15: =F15*D15 -> 79.2
C16: wortel | D16: 0.5 | E16: gr | F16: =VLOOKUP(C16,'Master Bahan'!$B$4:$G$44,4,0) -> 30 | G16: =F16*D16 -> 15
A18: NO | B18: NAMA | C18: INGREDIENTS | D18: QTY | E18: UOM | F18: HARSAT | G18: PRICE | H18: COST | I18: Energi | J18: TOTAL COST
B19: Dimsum ori topping beef | C19: Ayam Fillet Paha | D19: 20 | E19: gr | F19: =VLOOKUP(C19,'Master Bahan'!$B$4:$G$44,4,0) -> 57 | G19: =F19*D19 -> 1140 | H19: =SUM(G19:G32) -> 1600.4959 | I19: =H19*$I$1 -> 160.04959 | J19: =H19+I19 -> 1760.5455
C20: Telur Ayam | D20: 1.1 | E20: gr | F20: =VLOOKUP(C20,'Master Bahan'!$B$4:$G$44,4,0) -> 27 | G20: =F20*D20 -> 29.7
C21: Daun Bawang | D21: 1 | E21: gr | F21: =VLOOKUP(C21,'Master Bahan'!$B$4:$G$44,4,0) -> 20 | G21: =F21*D21 -> 20
C22: Bawang Putih | D22: 0.5 | E22: gr | F22: =VLOOKUP(C22,'Master Bahan'!$B$4:$G$44,4,0) -> 40 | G22: =F22*D22 -> 20
C23: Minyak Wijen | D23: 0.4 | E23: gr | F23: =VLOOKUP(C23,'Master Bahan'!$B$4:$G$44,4,0) -> 75 | G23: =F23*D23 -> 30
C24: Kecap Asin | D24: 0.1 | E24: gr | F24: =VLOOKUP(C24,'Master Bahan'!$B$4:$G$44,4,0) -> 60 | G24: =F24*D24 -> 6
C25: Saori saus Tiram | D25: 0.6 | E25: gr | F25: =VLOOKUP(C25,'Master Bahan'!$B$4:$G$44,4,0) -> 53 | G25: =F25*D25 -> 31.8
C26: Chicken Powder Knorr | D26: 0.4 | E26: gr | F26: =VLOOKUP(C26,'Master Bahan'!$B$4:$G$44,4,0) -> 105 | G26: =F26*D26 -> 42
C27: Sasa | D27: 0.3 | E27: gr | F27: =VLOOKUP(C27,'Master Bahan'!$B$4:$G$44,4,0) -> 50 | G27: =F27*D27 -> 15
C28: Garam | D28: 0.14 | E28: gr | F28: =VLOOKUP(C28,'Master Bahan'!$B$4:$G$44,4,0) -> 14 | G28: =F28*D28 -> 1.96
C29: Gula Pasir | D29: 0.5 | E29: gr | F29: =VLOOKUP(C29,'Master Bahan'!$B$4:$G$44,4,0) -> 18 | G29: =F29*D29 -> 9
C30: Kulit Dimsum | D30: 1 | E30: pcs | F30: =VLOOKUP(C30,'Master Bahan'!$B$4:$G$44,4,0) -> 132.97872 | G30: =F30*D30 -> 132.97872
C31: Tepung Tapioka | D31: 3.6 | E31: gr | F31: =VLOOKUP(C31,'Master Bahan'!$B$4:$G$44,4,0) -> 22 | G31: =F31*D31 -> 79.2
C32: beef patty | D32: 1 | E32: gr | F32: =VLOOKUP(C32,'Master Bahan'!$B$4:$G$44,4,0) -> 42.857143 | G32: =F32*D32 -> 42.857143
A34: NO | B34: NAMA | C34: INGREDIENTS | D34: QTY | E34: UOM | F34: HARSAT | G34: PRICE | H34: COST | I34: Energi | J34: TOTAL COST
B35: Dimsum isi Keju | C35: Ayam Fillet Paha | D35: 20 | E35: gr | F35: =VLOOKUP(C35,'Master Bahan'!$B$4:$G$44,4,0) -> 57 | G35: =F35*D35 -> 1140 | H35: =SUM(G35:G48) -> 1857.6387 | I35: =H35*$I$1 -> 185.76387 | J35: =H35+I35 -> 2043.4026
C36: Telur Ayam | D36: 1.1 | E36: gr | F36: =VLOOKUP(C36,'Master Bahan'!$B$4:$G$44,4,0) -> 27 | G36: =F36*D36 -> 29.7
C37: Daun Bawang | D37: 1 | E37: gr | F37: =VLOOKUP(C37,'Master Bahan'!$B$4:$G$44,4,0) -> 20 | G37: =F37*D37 -> 20
C38: Bawang Putih | D38: 0.5 | E38: gr | F38: =VLOOKUP(C38,'Master Bahan'!$B$4:$G$44,4,0) -> 40 | G38: =F38*D38 -> 20
C39: Minyak Wijen | D39: 0.4 | E39: gr | F39: =VLOOKUP(C39,'Master Bahan'!$B$4:$G$44,4,0) -> 75 | G39: =F39*D39 -> 30
C40: Kecap Asin | D40: 0.1 | E40: gr | F40: =VLOOKUP(C40,'Master Bahan'!$B$4:$G$44,4,0) -> 60 | G40: =F40*D40 -> 6
C41: Saori saus Tiram | D41: 0.6 | E41: gr | F41: =VLOOKUP(C41,'Master Bahan'!$B$4:$G$44,4,0) -> 53 | G41: =F41*D41 -> 31.8
C42: Chicken Powder Knorr | D42: 0.4 | E42: gr | F42: =VLOOKUP(C42,'Master Bahan'!$B$4:$G$44,4,0) -> 105 | G42: =F42*D42 -> 42
...

Sheet KOPI EVENT
B1: ` | I1: 0.1
A2: NO | B2: NAMA | C2: INGREDIENTS | D2: QTY | E2: UOM | F2: HARSAT | G2: PRICE | H2: COST | I2: Energi | J2: TOTAL COST
B3: KOPI SUSU JADUL | C3: NESCAFFE 30ml | D3: 1 | E3: set | F3: 1495.4 | G3: =F3*D3 -> 1495.4 | H3: =SUM(G3:G8) -> 6300.27 | I3: =H3*$I$1 -> 630.027 | J3: =H3+I3 -> 6930.297
B4: 1pcs | C4: SKM | D4: 9 | E4: gr | F4: 28.58 | G4: =F4*D4 -> 257.22
C5: CREAMER 100ml | D5: 1 | E5: gr | F5: 1151.25 | G5: =F5*D5 -> 1151.25
C6: Susu UHT | D6: 100 | E6: gr | F6: 20 | G6: =F6*D6 -> 2000
C7: Gula cair | D7: 11 | E7: gr | F7: 22.4 | G7: =F7*D7 -> 246.4
C8: Botol | D8: 1 | E8: gr | F8: 1150 | G8: =F8*D8 -> 1150
B10: Basic Preparation
A11: NO | B11: NAMA | C11: INGREDIENTS | D11: QTY | E11: UOM | F11: HARSAT | G11: PRICE | H11: COST | I11: Energi | J11: TOTAL COST
B12: NESCAFE BASIC | C12: NESCAFFE 20porsi(45g) | D12: 20 | E12: pcs | F12: 1350 | G12: =F12*D12 -> 27000 | H12: =SUM(G12:G13) -> 27189.474 | I12: =H12*$I$1 -> 2718.9474 | J12: =H12+I12 -> 29908.421 | L12: nescafe 45g beli 5
B13: 30ml | C13: Air Mineral | D13: 600 | E13: gr | F13: =VLOOKUP(C13,'Master Bahan'!$B$4:$G$44,4,0) -> 0.31578947 | G13: =F13*D13 -> 189.47368 | L13: creamer beli 5
L14: gula beli 1.500 g
A15: NO | B15: NAMA | C15: INGREDIENTS | D15: QTY | E15: UOM | F15: HARSAT | G15: PRICE | H15: COST | I15: Energi | J15: TOTAL COST | L15: skm beli 2
B16: Creamer | C16: Creamer | D16: 500 | E16: gr | F16: 40.6 | G16: =F16*D16 -> 20300 | H16: =SUM(G16:G17) -> 20931.579 | I16: =H16*$I$1 -> 2093.1579 | J16: =H16+I16 -> 23024.737 | L16: susu beli 10
B17: 100ml | C17: Air Mineral | D17: 2000 | E17: gr | F17: =VLOOKUP(C17,'Master Bahan'!$B$4:$G$44,4,0) -> 0.31578947 | G17: =F17*D17 -> 631.57894
A19: NO | B19: NAMA | C19: INGREDIENTS | D19: QTY | E19: UOM | F19: HARSAT | G19: PRICE | H19: COST | I19: Energi | J19: TOTAL COST
B20: Simple Syrup | C20: Gula | D20: 1000 | E20: gr | F20: 18 | G20: =F20*D20 -> 18000 | H20: =SUM(G20:G21) -> 18284.211 | I20: =H20*$I$1 -> 1828.4211 | J20: =H20+I20 -> 20112.632
B21: 10ml | C21: Air Mineral | D21: 900 | E21: gr | F21: =VLOOKUP(C21,'Master Bahan'!$B$4:$G$44,4,0) -> 0.31578947 | G21: =F21*D21 -> 284.21052
